<?xml version="1.0"?>
<robot xmlns:xacro="http://www.ros.org/wiki/xacro" name="my_robot">

    <xacro:property name="body_mass" value="25.0" />
    <xacro:property name="body_length" value="0.46" /> 
    <xacro:property name="body_width" value="0.35" /> 
    <xacro:property name="body_height" value="0.20" /> 

    <xacro:property name="wheel_radius" value="0.07" />
    <xacro:property name="wheel_thickness" value="0.07" />
    <xacro:property name="wheel_mass" value="3.0" />
    <xacro:property name="steering_mass" value="0.01" />

    <material name="black">
        <color rgba="0.1 0.1 0.1 1" />
    </material>
    <material name="white">
        <color rgba="1 1 1 1" />
    </material>

    <link name="base_footprint">
        <origin xyz="0 0 0" rpy="0 0 0" />
    </link>

    <link name="base_link" />

    <joint name="base_joint" type="fixed">
        <parent link="base_footprint" />
        <child link="base_link" />
        <origin xyz="0 0 0" rpy="0 0 0" />
    </joint>

    <link name="chassis_link">
        <inertial>
            <origin xyz="0 0 0" rpy="0 0 0" />
            <mass value="${body_mass}" />
            <inertia ixx="${body_mass/12 * (body_width*body_width + body_height*body_height)}"
                ixy="0" ixz="0"
                iyy="${body_mass/12 * (body_length*body_length + body_height*body_height)}" iyz="0"
                izz="${body_mass/12 * (body_width*body_width + body_length*body_length)}" />
        </inertial>
        <visual>
            <geometry>
                <box size="${body_length} ${body_width} ${body_height}" />
            </geometry>
            <material name="white" />
        </visual>
        <collision>
            <origin xyz="0 0 0.02" rpy="0 0 0" />
            <geometry>
                <box size="${body_length - 0.04} ${body_width - 0.04} ${body_height - 0.04}" />
            </geometry>
        </collision>
    </link>

    <joint name="chassis_joint" type="fixed">
        <parent link="base_link" />
        <child link="chassis_link" />
        <origin xyz="0 0 ${wheel_radius + body_height/2 - 0.001}" rpy="0 0 0" />
    </joint>

    <link name="fr_left_steer_link">
        <inertial>
            <origin xyz="0 0 0" rpy="0 0 0" />
            <mass value="${steering_mass}" />
            <inertia ixx="0.0001" ixy="0" ixz="0" iyy="0.0001" iyz="0" izz="0.0001" />
        </inertial>
    </link>

    <joint name="fr_left_steer_joint" type="revolute">
        <origin xyz="${body_length/2 - 0.05} ${body_width/2 + wheel_thickness/2} -${body_height/2}" rpy="0 0 0" />
        <parent link="chassis_link" />
        <child link="fr_left_steer_link" />
        <axis xyz="0 0 1" />
        <limit upper="0.6" lower="-0.6" effort="50.0" velocity="5.0" />
    </joint>

    <link name="fr_left_wheel_link">
        <inertial>
            <mass value="${wheel_mass}" />
            <inertia ixx="${wheel_mass/12*(3*wheel_radius*wheel_radius + wheel_thickness*wheel_thickness)}" ixy="0" ixz="0" iyy="${wheel_mass/12*(3*wheel_radius*wheel_radius + wheel_thickness*wheel_thickness)}" iyz="0" izz="${wheel_mass/2 * wheel_radius*wheel_radius}" />
        </inertial>
        <visual>
            <geometry><cylinder radius="${wheel_radius}" length="${wheel_thickness}" /></geometry>
            <material name="black" />
        </visual>
        <collision>
            <geometry><cylinder radius="${wheel_radius}" length="${wheel_thickness}" /></geometry>
        </collision>
    </link>

    <joint name="fr_left_wheel_joint" type="continuous">
        <origin xyz="0 0 0" rpy="-1.5708 0 0" />
        <parent link="fr_left_steer_link" />
        <child link="fr_left_wheel_link" />
        <axis xyz="0 0 1" />
        <dynamics friction="0.8" damping="0.5" />
        <limit effort="200" velocity="100" />
    </joint>

    <link name="fr_right_steer_link">
        <inertial>
            <origin xyz="0 0 0" rpy="0 0 0" />
            <mass value="${steering_mass}" />
            <inertia ixx="0.0001" ixy="0" ixz="0" iyy="0.0001" iyz="0" izz="0.0001" />
        </inertial>
    </link>

    <joint name="fr_right_steer_joint" type="revolute">
        <origin xyz="${body_length/2 - 0.05} -${body_width/2 + wheel_thickness/2} -${body_height/2}" rpy="0 0 0" />
        <parent link="chassis_link" />
        <child link="fr_right_steer_link" />
        <axis xyz="0 0 1" />
        <limit upper="0.6" lower="-0.6" effort="50.0" velocity="5.0" />
    </joint>

    <link name="fr_right_wheel_link">
        <inertial>
            <mass value="${wheel_mass}" />
            <inertia ixx="${wheel_mass/12*(3*wheel_radius*wheel_radius + wheel_thickness*wheel_thickness)}" ixy="0" ixz="0" iyy="${wheel_mass/12*(3*wheel_radius*wheel_radius + wheel_thickness*wheel_thickness)}" iyz="0" izz="${wheel_mass/2 * wheel_radius*wheel_radius}" />
        </inertial>
        <visual>
            <geometry><cylinder radius="${wheel_radius}" length="${wheel_thickness}" /></geometry>
            <material name="black" />
        </visual>
        <collision>
            <geometry><cylinder radius="${wheel_radius}" length="${wheel_thickness}" /></geometry>
        </collision>
    </link>

    <joint name="fr_right_wheel_joint" type="continuous">
        <origin xyz="0 0 0" rpy="-1.5708 0 0" />
        <parent link="fr_right_steer_link" />
        <child link="fr_right_wheel_link" />
        <axis xyz="0 0 1" />
        <dynamics friction="0.8" damping="0.5" />
        <limit effort="200" velocity="100" />
    </joint>

    <link name="re_left_wheel_link">
        <inertial>
            <mass value="${wheel_mass}" />
            <inertia ixx="${wheel_mass/12*(3*wheel_radius*wheel_radius + wheel_thickness*wheel_thickness)}" ixy="0" ixz="0" iyy="${wheel_mass/12*(3*wheel_radius*wheel_radius + wheel_thickness*wheel_thickness)}" iyz="0" izz="${wheel_mass/2 * wheel_radius*wheel_radius}" />
        </inertial>
        <visual>
            <geometry><cylinder radius="${wheel_radius}" length="${wheel_thickness}" /></geometry>
            <material name="black" />
        </visual>
        <collision>
            <geometry><cylinder radius="${wheel_radius}" length="${wheel_thickness}" /></geometry>
        </collision>
    </link>

    <joint name="re_left_wheel_joint" type="continuous">
        <origin xyz="-${body_length/2 - 0.05} ${body_width/2 + wheel_thickness/2} -${body_height/2}" rpy="-1.5708 0 0" />
        <parent link="chassis_link" />
        <child link="re_left_wheel_link" />
        <axis xyz="0 0 1" />
        <dynamics friction="0.8" damping="0.5" />
        <limit effort="200" velocity="100" />
    </joint>

    <link name="re_right_wheel_link">
        <inertial>
            <mass value="${wheel_mass}" />
            <inertia ixx="${wheel_mass/12*(3*wheel_radius*wheel_radius + wheel_thickness*wheel_thickness)}" ixy="0" ixz="0" iyy="${wheel_mass/12*(3*wheel_radius*wheel_radius + wheel_thickness*wheel_thickness)}" iyz="0" izz="${wheel_mass/2 * wheel_radius*wheel_radius}" />
        </inertial>
        <visual>
            <geometry><cylinder radius="${wheel_radius}" length="${wheel_thickness}" /></geometry>
            <material name="black" />
        </visual>
        <collision>
            <geometry><cylinder radius="${wheel_radius}" length="${wheel_thickness}" /></geometry>
        </collision>
    </link>

    <joint name="re_right_wheel_joint" type="continuous">
        <origin xyz="-${body_length/2 - 0.05} -${body_width/2 + wheel_thickness/2} -${body_height/2}" rpy="-1.5708 0 0" />
        <parent link="chassis_link" />
        <child link="re_right_wheel_link" />
        <axis xyz="0 0 1" />
        <dynamics friction="0.8" damping="0.5" />
        <limit effort="200" velocity="100" />
    </joint>

    <link name="laser_link">
        <visual>
            <geometry><cylinder length="0.03" radius="0.025"/></geometry>
            <origin rpy="0 0 0" xyz="0 0 -0.01"/>
            <material name="white" />
        </visual>
        <inertial>
            <mass value="0.1"/>
            <inertia ixx="0.001" ixy="0.0" ixz="0.0" iyy="0.001" iyz="0.0" izz="0.001"/>
            <origin xyz="0 0 -0.01"/>
        </inertial>
    </link>

    <joint name="laser_joint" type="fixed">
        <parent link="chassis_link"/> <child link="laser_link"/>
        <origin rpy="0 0 0" xyz="0 0 ${body_height/2 + 0.02}"/>
    </joint>

    <gazebo reference="laser_link">
        <material>Gazebo/Black</material>
        <sensor name="laser_sensor" type="ray">
            <always_on>true</always_on>
            <visualize>true</visualize>
            <update_rate>10</update_rate>
            <pose>0 0 0 0 0 0</pose>
            <ray>
                <scan>
                    <horizontal>
                        <samples>360</samples>
                        <resolution>1.000000</resolution>
                        <min_angle>0.000000</min_angle>
                        <max_angle>6.280000</max_angle>
                    </horizontal>
                </scan>
                <range>
                    <min>0.0000</min>
                    <max>25.0</max>
                    <resolution>0.015000</resolution>
                </range>
                <noise>
                    <type>gaussian</type>
                    <mean>0.0</mean>
                    <stddev>0.01</stddev>
                </noise>
            </ray>
            <plugin name="laserscan" filename="libgazebo_ros_ray_sensor.so">
                <ros><remapping>~/out:=scan</remapping></ros>
                <output_type>sensor_msgs/LaserScan</output_type>
                <frame_name>laser_link</frame_name>
            </plugin>
        </sensor>
    </gazebo>

    <link name="imu_link">
        <visual>
            <origin xyz="0 0 0" rpy="0 0 0"/>
            <geometry><box size="0.02 0.02 0.02"/></geometry>
            <material name="black"/>
        </visual>
        <inertial>
            <mass value="0.1"/>
            <inertia ixx="0.00019" ixy="0" ixz="0" iyy="0.00019" iyz="0" izz="0.00036"/>
        </inertial>
    </link>
    
    <joint name="imu_joint" type="fixed">
        <parent link="chassis_link" /> <child link="imu_link" />
        <origin xyz="0 0 ${body_height/2 + 0.01}" />
    </joint>

    <gazebo reference="imu_link">
        <material>Gazebo/Black</material>
        <sensor name="imu_sensor" type="imu">
            <plugin filename="libgazebo_ros_imu_sensor.so" name="imu_plugin">
                <ros>
                    <namespace>/</namespace>
                    <remapping>~/out:=imu</remapping>
                </ros>
                <initial_orientation_as_reference>false</initial_orientation_as_reference>
            </plugin>
            <always_on>true</always_on>
            <update_rate>100</update_rate>
            <visualize>true</visualize>
        </sensor>
    </gazebo>

    <xacro:macro name="wheel_friction" params="link_name">
        <gazebo reference="${link_name}">
            <material>Gazebo/DarkGrey</material>
            <mu1>1.2</mu1>
            <mu2>1.2</mu2>
            <kp>10000000.0</kp>
            <kd>1.0</kd>
            <minDepth>0.001</minDepth> </gazebo>
    </xacro:macro>

    <xacro:wheel_friction link_name="fr_left_wheel_link" />
    <xacro:wheel_friction link_name="fr_right_wheel_link" />
    <xacro:wheel_friction link_name="re_left_wheel_link" />
    <xacro:wheel_friction link_name="re_right_wheel_link" />

</robot>