<?xml version="1.0"?>
<robot xmlns:xacro="http://www.ros.org/wiki/xacro">
    <gazebo reference="chassis_link">
        <material>Gazebo/White</material>
        <mu1>0.5</mu1>
        <mu2>0.5</mu2>
    </gazebo>
    <gazebo reference="fr_left_wheel_link">
        <material>Gazebo/DarkGrey</material>
        <mu1>1.2</mu1>
        <mu2>1.2</mu2>
    </gazebo>
    <gazebo reference="fr_right_wheel_link">
        <material>Gazebo/DarkGrey</material>
        <mu1>1.2</mu1>
        <mu2>1.2</mu2>
    </gazebo>
    <gazebo reference="re_left_wheel_link">
        <material>Gazebo/DarkGrey</material>
        <mu1>1.2</mu1>
        <mu2>1.2</mu2>
    </gazebo>
    <gazebo reference="re_right_wheel_link">
        <material>Gazebo/DarkGrey</material>
        <mu1>1.2</mu1>
        <mu2>1.2</mu2>
    </gazebo>
    <gazebo reference="virtual_steer_link">
        <material>Gazebo/Yellow</material>
    </gazebo>

    <gazebo>
        <plugin name="gazebo_ros_joint_state_publisher" filename="libgazebo_ros_joint_state_publisher.so">
            <update_rate>100</update_rate>
            <joint_name>fr_right_steer_joint</joint_name>
            <joint_name>fr_right_wheel_joint</joint_name>
            <joint_name>fr_left_steer_joint</joint_name>
            <joint_name>fr_left_wheel_joint</joint_name>
            <joint_name>re_right_wheel_joint</joint_name>
            <joint_name>re_left_wheel_joint</joint_name>
            <joint_name>virtual_steering_wheel_joint</joint_name>
        </plugin>
    </gazebo>

    <gazebo>
        <plugin name="gazebo_ros_joint_pose_trajectory" filename="libgazebo_ros_joint_pose_trajectory.so">
            <update_rate>2</update_rate>
        </plugin>
    </gazebo>

    <gazebo>
        <plugin name='gazebo_ackermann_drive' filename='libgazebo_ros_ackermann_drive.so'>
            <ros>
                <remapping>cmd_vel:=cmd_vel</remapping>
                <remapping>odom:=odom/bot</remapping>
                <remapping>distance:=distance/bot</remapping>
            </ros>

            <update_rate>100.0</update_rate>

            <front_left_joint>fr_left_wheel_joint</front_left_joint>
            <front_right_joint>fr_right_wheel_joint</front_right_joint>
            <rear_left_joint>re_left_wheel_joint</rear_left_joint>
            <rear_right_joint>re_right_wheel_joint</rear_right_joint>
            <left_steering_joint>fr_left_steer_joint</left_steering_joint>
            <right_steering_joint>fr_right_steer_joint</right_steering_joint>
            <steering_wheel_joint>virtual_steering_wheel_joint</steering_wheel_joint>

            <wheel_base>0.36</wheel_base>       <wheel_separation>0.42</wheel_separation> <wheel_diameter>0.14</wheel_diameter> <max_steer>0.6</max_steer> <max_steering_angle>1.570796</max_steering_angle> <max_speed>5.0</max_speed>

            <left_steering_pid_gain>500 0 1</left_steering_pid_gain>
            <left_steering_i_range>0 0</left_steering_i_range>
            <right_steering_pid_gain>500 0 1</right_steering_pid_gain>
            <right_steering_i_range>0 0</right_steering_i_range>
            <linear_velocity_pid_gain>500 0 1</linear_velocity_pid_gain>
            <linear_velocity_i_range>0 0</linear_velocity_i_range>

            <publish_odom>true</publish_odom>
            <publish_odom_tf>true</publish_odom_tf>
            <publish_wheel_tf>false</publish_wheel_tf>
            <publish_distance>true</publish_distance>

            <odometry_frame>odom</odometry_frame>
            <robot_base_frame>base_footprint</robot_base_frame>
        </plugin>
    </gazebo>

    <link name="virtual_steer_link">
        <visual>
            <origin xyz="0.0 0.0 0.0" rpy="0.0 0.0 0.0" />
            <geometry>
                <box size="0.01 0.15 0.075" />
            </geometry>
            <material name="">
                <color rgba="1.0 1.0 0.0 1" />
            </material>
        </visual>
        <inertial>
            <origin xyz="0.0 0.0 0.0" rpy="0.0 0.0 0.0" />
            <mass value="0.001" />
            <inertia ixx="0.0001" ixy="0.0" ixz="0.0" iyy="0.0001" iyz="0.0" izz="0.0001" />
        </inertial>
    </link>
    
    <joint name="virtual_steering_wheel_joint" type="revolute">
        <origin xyz="-0.23 0.0 0.0" rpy="0.0 0.0 0.0" />
        <parent link="chassis_link" />
        <child link="virtual_steer_link" />
        <axis xyz="-1 0 0" />
        <limit lower="-3.14" upper="3.14" effort="200" velocity="20" />
    </joint>

</robot>